Workbook

Sheet 00_Executive_Dashboard
A1: VN-INDEX QUANTITATIVE SCORING SYSTEM — EXECUTIVE DASHBOARD
A2: Institutional quarterly macro-quant model | formula-driven | point-in-time inputs | 2021-Q1 to latest available quarter
A5: LATEST QUARTER | B5: CALIBRATED ACTION | C5: CALIBRATED SCORE | D5: EQUITY ALLOCATION | E5: RAW COMPOSITE
A6: =INDEX('05_Composite_Calibration'!A5:A28,COUNTA('05_Composite_Calibration'!A5:A28)) | B6: =INDEX('05_Composite_Calibration'!K5:K28,COUNTA('05_Composite_Calibration'!A5:A28)) | C6: =INDEX('05_Composite_Calibration'!J5:J28,COUNTA('05_Composite_Calibration'!A5:A28)) | D6: =INDEX('05_Composite_Calibration'!L5:L28,COUNTA('05_Composite_Calibration'!A5:A28)) | E6: =INDEX('05_Composite_Calibration'!D5:D28,COUNTA('05_Composite_Calibration'!A5:A28))
A9: LATEST-QUARTER SIX-PILLAR DECOMPOSITION
A10: Pillar | B10: Weight | C10: Raw Score | D10: Weighted Contribution | E10: % of Composite | F10: Assessment
A11: Macro & Monetary | B11: ='01_Model_Config'!C6 | C11: =INDEX('04_Pillar_Calculation'!C5:C28,COUNTA('04_Pillar_Calculation'!A5:A28)) | D11: =INDEX('04_Pillar_Calculation'!K5:K28,COUNTA('04_Pillar_Calculation'!A5:A28)) | E11: =D11/$D$17 | F11: =IF(C11>=65,"Favorable",IF(C11>=50,"Neutral","Unfavorable"))
A12: Global & Intermarket | B12: ='01_Model_Config'!C7 | C12: =INDEX('04_Pillar_Calculation'!D5:D28,COUNTA('04_Pillar_Calculation'!A5:A28)) | D12: =INDEX('04_Pillar_Calculation'!L5:L28,COUNTA('04_Pillar_Calculation'!A5:A28)) | E12: =D12/$D$17 | F12: =IF(C12>=65,"Favorable",IF(C12>=50,"Neutral","Unfavorable"))
A13: Valuation & Leverage | B13: ='01_Model_Config'!C8 | C13: =INDEX('04_Pillar_Calculation'!E5:E28,COUNTA('04_Pillar_Calculation'!A5:A28)) | D13: =INDEX('04_Pillar_Calculation'!M5:M28,COUNTA('04_Pillar_Calculation'!A5:A28)) | E13: =D13/$D$17 | F13: =IF(C13>=65,"Favorable",IF(C13>=50,"Neutral","Unfavorable"))
A14: Econometric Models | B14: ='01_Model_Config'!C9 | C14: =INDEX('04_Pillar_Calculation'!F5:F28,COUNTA('04_Pillar_Calculation'!A5:A28)) | D14: =INDEX('04_Pillar_Calculation'!N5:N28,COUNTA('04_Pillar_Calculation'!A5:A28)) | E14: =D14/$D$17 | F14: =IF(C14>=65,"Favorable",IF(C14>=50,"Neutral","Unfavorable"))
A15: Machine Learning | B15: ='01_Model_Config'!C10 | C15: =INDEX('04_Pillar_Calculation'!G5:G28,COUNTA('04_Pillar_Calculation'!A5:A28)) | D15: =INDEX('04_Pillar_Calculation'!O5:O28,COUNTA('04_Pillar_Calculation'!A5:A28)) | E15: =D15/$D$17 | F15: =IF(C15>=65,"Favorable",IF(C15>=50,"Neutral","Unfavorable"))
A16: Market Structure | B16: ='01_Model_Config'!C11 | C16: =INDEX('04_Pillar_Calculation'!H5:H28,COUNTA('04_Pillar_Calculation'!A5:A28)) | D16: =INDEX('04_Pillar_Calculation'!P5:P28,COUNTA('04_Pillar_Calculation'!A5:A28)) | E16: =D16/$D$17 | F16: =IF(C16>=65,"Favorable",IF(C16>=50,"Neutral","Unfavorable"))
A17: COMPOSITE TOTAL | B17: =SUM(B11:B16) | C17: =SUMPRODUCT(B11:B16,C11:C16) | D17: =SUM(D11:D16) | E17: =SUM(E11:E16) | F17: =INDEX('05_Composite_Calibration'!E5:E28,COUNTA('05_Composite_Calibration'!A5:A28))
A20: BACKTEST & SIGNAL EFFICACY SUMMARY
A21: Metric | B21: Formula Result | C21: Acceptance Reference | D21: Interpretation
A22: Strategy CAGR | B22: ='10_Backtest_Efficacy'!B33 | C22: ≈ 5.74% | D22: Annualized dashboard-compatible strategy return
A23: Maximum Drawdown | B23: ='10_Backtest_Efficacy'!B34 | C23: ≈ -9.02% | D23: Worst peak-to-trough strategy decline
A24: Annualized Volatility | B24: ='10_Backtest_Efficacy'!B35 | C24: ≈ 7.70% | D24: Quarterly volatility annualized by √4
A25: Sharpe Ratio | B25: ='10_Backtest_Efficacy'!B36 | C25: ≈ 0.16 | D25: CAGR less configured risk-free rate, divided by volatility
A26: Spearman Rank IC | B26: ='10_Backtest_Efficacy'!B37 | C26: ≈ 0.1927 | D26: Raw score rank vs strict point-in-time quarter return rank
A27: Directional Hit Rate | B27: ='10_Backtest_Efficacy'!B38 | C27: Formula | D27: Action-direction agreement with dashboard forward return

Sheet 01_Model_Config
A1: VN-INDEX MODEL CONFIGURATION — SINGLE SOURCE OF TRUTH
A2: Weights, score bands, calibration parameters, signal gains and backtest assumptions
A4: 1. PILLAR WEIGHTS
A5: Pillar Code | B5: Pillar Name | C5: Weight | D5: Primary Inputs
A6: macro_monetary | B6: Macro & Monetary | C6: 0.25 | D6: Rates, FX, M2 and sovereign curve
A7: global_intermarket | B7: Global & Intermarket | C7: 0.2 | D7: DXY, US10Y, foreign flows, JPY and oil
A8: valuation_leverage | B8: Valuation & Leverage | C8: 0.2 | D8: P/E, P/B, EYG and margin risk
A9: quant_model | B9: Econometric Models | C9: 0.15 | D9: MLR, VAR and Granger causality
A10: ml_forecast | B10: Machine Learning | C10: 0.1 | D10: XGBoost walk-forward quality and signal
A11: market_structure | B11: Market Structure | C11: 0.1 | D11: FTSE, ADTV and ETF flows
A12: TOTAL WEIGHT | C12: =SUM(C6:C11) | D12: Must equal 100%
A14: 2. SCORE BANDS & ALLOCATION MATRIX
A15: Minimum | B15: Maximum | C15: Action | D15: Emoji | E15: Suggested Allocation | F15: Model Mid-Weight | G15: Risk Posture
A16: 80 | B16: 100 | C16: BUY | D16: 🟢 | E16: 85–100% Equities | F16: 0.925 | G16: Aggressive risk-on
A17: 65 | B17: 79.9999 | C17: ACCUMULATE | D17: 🔵 | E17: 70–85% Equities | F17: 0.775 | G17: Constructive risk-on
A18: 50 | B18: 64.9999 | C18: HOLD | D18: 🟡 | E18: 40–60% Equities | F18: 0.5 | G18: Balanced / neutral
A19: 35 | B19: 49.9999 | C19: REDUCE | D19: 🟠 | E19: 20–40% Equities | F19: 0.3 | G19: Defensive
A20: 0 | B20: 34.9999 | C20: SELL | D20: 🔴 | E20: 0–20% Equities | F20: 0.1 | G20: Capital preservation
A22: 3. EXPANDING CALIBRATION PARAMETERS (v2 — winsorized, guard-railed)
A23: Parameter | B23: Value | C23: Role
A24: center | B24: 50 | C24: Calibrated-score center
A25: z_scale | B25: 15 | C25: Points per historical σ
A26: min_history | B26: 4 | C26: Required prior quarters
A27: clip_low | B27: 0 | C27: Score floor
A28: clip_high | B28: 100 | C28: Score cap
A30: 4. MODEL GAINS & BACKTEST ASSUMPTIONS
A31: Parameter | B31: Value | C31: Formula / Interpretation
A32: MLR gain | B32: 20000 | C32: 50 + forecast/day × gain
A33: VAR gain | B33: 5000 | C33: 50 + T+5 return × gain
A34: Periods per year | B34: 4 | C34: Quarterly annualization
A35: Initial NAV | B35: 100 | C35: Strategy and benchmark base
A36: Risk-free rate | B36: 0.045 | C36: Annual Sharpe hurdle
A38: 5. CALIBRATION v2 ROBUSTNESS GUARDS
A39: Parameter | B39: Value | C39: Role
A40: min_std | B40: 5 | C40: σ prior floor: tiny-sample σ cannot inflate z (floor ≈ long-run composite dispersion)
A41: z_cap | B41: 3 | C41: Winsorise z at ±3σ → response saturates near 5/95; 0/100 unreachable
A42: max_dist_from_raw | B42: 25 | C42: Action signal may not deviate more than ±25 pts from the raw composite

Sheet 02_Market_Inputs
A1: POINT-IN-TIME MARKET & MODEL INPUT LEDGER
A2: Every Quarter t input is dated at the last available session of t−1; the separate outcome close is never used in scoring
A4: Quarter | B4: As-of Date | C4: As-of VN-Index Close | D4: Quarter-End Outcome Close | E4: VN1Y % | F4: ΔVN1Y pp | G4: VN10Y % | H4: Spread pp | I4: USD/VND Z | J4: M2 YoY % | K4: DXY Z | L4: US10Y % | M4: NFF Z | N4: NFF % MC | O4: USD/JPY Z | P4: Oil Shock | Q4: P/E Z | R4: P/B Z | S4: Margin Risk | T4: EYG Z | U4: Valuation Composite | V4: ADTV QoQ | W4: FTSE Status | X4: Months to Rebal | Y4: ETF Flow Z | Z4: ETF % MC
A5: 2021-Q1 | B5: 2020-12-31 | C5: 1103.87 | D5: 1191.44 | E5: 0.4326 | F5: -0.064174 | G5: 2.0246 | H5: 1.3872 | I5: -2.68 | J5: 14.53 | K5: -1.57 | L5: 0.92 | M5: -2.4315 | N5: -0.4358 | O5: -1.76 | P5: 20.7 | S5: 0 | V5: 0.606722 | W5: unknown | X5: 3 | Y5: 1.8116 | Z5: 0.0559
A6: 2021-Q2 | B6: 2021-03-31 | C6: 1191.44 | D6: 1408.55 | E6: 0.464 | F6: -0.013805 | G6: 2.2209 | H6: 1.669 | I6: 0.6 | J6: 14.53 | K6: 2.39 | L6: 1.75 | M6: -4.0648 | N6: -0.9813 | O6: 1.95 | P6: 19.9 | S6: 4 | V6: 0.422295 | W6: unknown | X6: 3 | Y6: 5.9155 | Z6: 0.1566
A7: 2021-Q3 | B7: 2021-06-30 | C7: 1408.55 | D7: 1342.06 | E7: 0.5013 | F7: 0.001505 | G7: 2.057 | H7: 1.3519 | I7: 0.18 | J7: 14.53 | K7: 1.96 | L7: 1.44 | M7: -0.5589 | N7: -0.3302 | O7: 1.5 | P7: 12 | S7: 0 | V7: 0.111991 | W7: unknown | X7: 3 | Y7: 0.4047 | Z7: 0.0557
A8: 2021-Q4 | B8: 2021-09-30 | C8: 1342.06 | D8: 1498.28 | E8: 0.5017 | F8: 0.001321 | G8: 1.9128 | H8: 1.2312 | I8: -0.65 | J8: 14.53 | K8: 2.89 | L8: 1.53 | M8: 0.0507 | N8: -0.1213 | O8: 3.84 | P8: 21.8 | S8: 15 | V8: -0.063721 | W8: unknown | X8: 3 | Y8: -1.5849 | Z8: -0.0332
A9: 2022-Q1 | B9: 2021-12-31 | C9: 1498.28 | D9: 1492.15 | E9: 0.4944 | F9: 0.017019 | G9: 2.007 | H9: 1.4797 | I9: -0.05 | J9: 10.66 | K9: 0.33 | L9: 1.51 | M9: -0.4292 | N9: -0.286 | O9: 1.82 | P9: 19.1 | Q9: 1.3716286 | R9: 1.724412 | S9: 1 | T9: -0.89270763 | V9: 0.33276 | W9: unknown | X9: 3 | Y9: -0.3814 | Z9: 0.0142
A10: 2022-Q2 | B10: 2022-03-31 | C10: 1492.15 | D10: 1197.6 | E10: 1.3143 | F10: -0.060524 | G10: 2.424 | H10: 0.9445 | I10: 1.02 | J10: 10.66 | K10: 1.03 | L10: 2.33 | M10: 0.1512 | N10: -0.0992 | O10: 2.24 | P10: 43.6 | Q10: 1.2473397 | R10: 1.5929063 | S10: 11 | T10: -0.85124281 | V10: -0.076852 | W10: unknown | X10: 3 | Y10: -0.7594 | Z10: -0.0039
A11: 2022-Q3 | B11: 2022-06-30 | C11: 1197.6 | D11: 1132.11 | E11: 1.8151 | F11: -0.005296 | G11: 3.2011 | H11: 1.1263 | I11: 1.35 | J11: 10.66 | K11: 1.18 | L11: 2.97 | M11: 0.6204 | N11: 0.0525 | O11: 1.87 | P11: 21.1 | Q11: 0.0061852326 | R11: -0.12402402 | S11: 80 | T11: -0.39697033 | V11: -0.295489 | W11: unknown | X11: 3 | Y11: 0.4218 | Z11: 0.0476
A12: 2022-Q4 | B12: 2022-09-30 | C12: 1132.11 | D12: 1007.09 | E12: 4.0572 | F12: 0.202285 | G12: 4.674 | H12: 0.5962 | I12: 2.82 | J12: 10.66 | K12: 1.68 | L12: 3.8 | M12: 0.5065 | N12: 0.0255 | O12: 1.52 | P12: 17.4 | Q12: -0.21260386 | R12: -0.41728564 | S12: 54 | T12: -0.42088188 | V12: -0.087319 | W12: unknown | X12: 3 | Y12: -1.4748 | Z12: -0.0348
A13: 2023-Q1 | B13: 2022-12-30 | C13: 1007.09 | D13: 1064.64 | E13: 4.6775 | F13: -0.03116 | G13: 4.8245 | H13: 0.1576 | I13: -1.39 | J13: 10.66 | K13: -1.29 | L13: 3.88 | M13: 2.1533 | N13: 0.5325 | O13: -1.44 | P13: 22 | Q13: -0.69468194 | R13: -1.0494135 | S13: 35 | T13: -0.049359684 | V13: 0.192768 | W13: unknown | X13: 3 | Y13: 0.6843 | Z13: 0.0567
A14: 2023-Q2 | B14: 2023-03-31 | C14: 1064.64 | D14: 1120.18 | E14: 3.3908 | F14: -0.068954 | G14: 3.5545 | H14: 0.1561 | I14: -0.76 | J14: 6.15 | K14: -0.72 | L14: 3.49 | M14: 0.5327 | N14: 0.0941 | O14: 0.32 | P14: 17.3 | Q14: -0.48426225 | R14: -0.74706526 | S14: 21 | T14: -0.0075394935 | V14: -0.191478 | W14: unknown | X14: 3 | Y14: -0.24 | Z14: 0.0169
A15: 2023-Q3 | B15: 2023-06-30 | C15: 1120.18 | D15: 1154.15 | E15: 2.1614 | F15: -0.006956 | G15: 2.5684 | H15: 0.3695 | I15: 2.97 | J15: 6.15 | K15: 0.3 | L15: 3.82 | M15: -0.124 | N15: -0.1149 | O15: 2.05 | P15: 17.1 | Q15: 0.055005503 | R15: -0.10455154 | S15: 7 | T15: -0.21206364 | V15: 0.399685 | W15: unknown | X15: 3 | Y15: -0.7902 | Z15: -0.0072
A16: 2023-Q4 | B16: 2023-09-29 | C16: 1154.15 | D16: 1129.93 | E16: 1.868 | F16: 0.029032 | G16: 2.4762 | H16: 0.5369 | I16: 1.82 | J16: 6.15 | K16: 1.57 | L16: 4.57 | M16: 0.0585 | N16: -0.0579 | O16: 1.48 | P16: 13.5 | Q16: 0.34176328 | R16: 0.36886409 | S16: 33 | T16: -0.34595104 | V16: 0.288734 | W16: unknown | X16: 3 | Y16: -1.4875 | Z16: -0.0384
A17: 2024-Q1 | B17: 2023-12-29 | C17: 1129.93 | D17: 1284.09 | E17: 1.6115 | F17: 0.010374 | G17: 2.2174 | H17: 0.5376 | I17: -0.96 | J17: 6.15 | K17: -1.73 | L17: 3.87 | M17: -0.2633 | N17: -0.1571 | O17: -2.03 | P17: 14.8 | Q17: 0.42314624 | R17: 0.39293487 | S17: 10 | T17: -0.33528921 | V17: -0.288754 | W17: unknown | X17: 3 | Y17: -1.7808 | Z17: -0.0563
A18: 2024-Q2 | B18: 2024-03-29 | C18: 1284.09 | D18: 1245.32 | E18: 1.5461 | F18: 0.022309 | G18: 2.4651 | H18: 0.8931 | I18: 1.68 | J18: 12.46 | K18: 1.38 | L18: 4.21 | M18: -0.0101 | N18: -0.0825 | O18: 1.39 | P18: 12 | Q18: 1.1112195 | R18: 1.255887 | S18: 2 | T18: -0.66956951 | V18: 0.260258 | W18: unknown | X18: 3 | Y18: -1.7549 | Z18: -0.0627
A19: 2024-Q3 | B19: 2024-06-28 | C19: 1245.32 | D19: 1287.94 | E19: 2.0678 | F19: 0.0517 | G19: 2.7738 | H19: 0.6057 | I19: 0.56 | J19: 12.46 | K19: 1.03 | L19: 4.34 | M19: -0.919 | N19: -0.3509 | O19: 2.26 | P19: 9 | Q19: 1.2951725 | R19: 1.4665091 | S19: 19 | T19: -0.78549701 | V19: -0.070967 | W19: unknown | X19: 3 | Y19: -2.04 | Z19: -0.0838
A20: 2024-Q4 | B20: 2024-09-30 | C20: 1287.94 | D20: 1266.78 | E20: 1.8875 | F20: -0.044628 | G20: 2.8461 | H20: 0.8262 | I20: -1.33 | J20: 12.46 | K20: -1.09 | L20: 3.8 | M20: -0.2976 | N20: -0.1789 | O20: -0.92 | P20: 13.3 | Q20: 1.2345458 | R20: 1.3854181 | S20: 2 | T20: -0.77529072 | V20: -0.22597 | W20: unknown | X20: 3 | Y20: -0.3091 | Z20: -0.0056
... A28: 2026-Q4 | B28: 2026-09-30 | C28: 1768.62 | D28: 1749.3 | E28: 3.8244862 | F28: -0.006669987 | G28: 4.4903384 | H28: 0.56417624 | I28: -1.2884 | J28: 14.98 | K28: 1.5610034 | L28: 5.2930002 | M28: -0.12209485 | N28: -0.18012223 | O28: -0.5758619 | P28: 43.812594 | Q28: 0.75094412 | R28: 0.63804465 | S28: 20.398842 | T28: -1.2227083 | V28: -0.12261541 | W28: confirmed | X28: 3 | Y28: -0.11475527 | Z28: 0.0013040779

Sheet 03_Factor_SubScores
A1: FORMULA-NORMALIZED FACTOR SUB-SCORES
A2: All 0–100 factor scores are live formulas sourced from the point-in-time input and model ledgers
A4: Quarter | B4: As-of Date | C4: VN1Y | D4: IR Trend | E4: FX | F4: M2 | G4: VN Bonds | H4: DXY | I4: US10Y | J4: NFF | K4: JPY Carry | L4: Oil Shock | M4: P/E | N4: P/B | O4: Margin | P4: EYG | Q4: MLR Signal | R4: VAR Signal | S4: ML Quality | T4: ML Direction | U4: FTSE + Rebal | V4: ADTV | W4: ETF Flow
A5: ='02_Market_Inputs'!A5 | B5: ='02_Market_Inputs'!B5 | C5: =IF(ISBLANK('02_Market_Inputs'!E5),50,MIN(100,MAX(0,100-('02_Market_Inputs'!E5-1)*14))) | D5: =IF(ISBLANK('02_Market_Inputs'!F5),50,MIN(100,MAX(0,50-'02_Market_Inputs'!F5*100))) | E5: =IF(ISBLANK('02_Market_Inputs'!I5),50,MIN(100,MAX(0,50-'02_Market_Inputs'!I5*15))) | F5: =IF(ISBLANK('02_Market_Inputs'!J5),50,MIN(100,MAX(0,80-ABS('02_Market_Inputs'!J5-12)*4))) | G5: =IF(OR(ISBLANK('02_Market_Inputs'!G5),ISBLANK('02_Market_Inputs'!H5)),50,(MIN(100,MAX(0,100-('02_Market_Inputs'!G5-2.5)*28.5))+MIN(100,MAX(0,('02_Market_Inputs'!H5+0.2)*58)))/2) | H5: =IF(ISBLANK('02_Market_Inputs'!K5),50,MIN(100,MAX(0,50-'02_Market_Inputs'!K5*20))) | I5: =IF(ISBLANK('02_Market_Inputs'!L5),50,MIN(100,MAX(0,100-'02_Market_Inputs'!L5*20))) | J5: =IF(ISBLANK('02_Market_Inputs'!M5),50,MIN(100,MAX(0,50+'02_Market_Inputs'!M5*15))) | K5: =IF(ISBLANK('02_Market_Inputs'!O5),50,MIN(100,MAX(0,50+'02_Market_Inputs'!O5*15))) | L5: =IF(OR(ISBLANK('02_Market_Inputs'!P5),'02_Market_Inputs'!P5<=0),50,MIN(100,MAX(0,100-'02_Market_Inputs'!P5))) | M5: =IF(ISBLANK('02_Market_Inputs'!Q5),50,MIN(100,MAX(0,50-'02_Market_Inputs'!Q5*25))) | N5: =IF(ISBLANK('02_Market_Inputs'!R5),50,MIN(100,MAX(0,50-'02_Market_Inputs'!R5*25))) | O5: =IF(ISBLANK('02_Market_Inputs'!S5),50,MIN(100,MAX(0,100-'02_Market_Inputs'!S5))) | P5: =IF(ISBLANK('02_Market_Inputs'!T5),50,MIN(100,MAX(0,50+'02_Market_Inputs'!T5*25))) | Q5: ='06_MLR_Regression'!H5 | R5: ='07_VAR_Granger'!K5 | S5: ='08_ML_Validation'!K5 | T5: ='08_ML_Validation'!L5 | U5: =IF('02_Market_Inputs'!W5="completed",85,IF('02_Market_Inputs'!W5="confirmed",75,IF('02_Market_Inputs'!W5="pending",55,50)))+IF('02_Market_Inputs'!X5<=1,20,IF('02_Market_Inputs'!X5<=2,12,IF('02_Market_Inputs'!X5<=3,6,0))) | V5: =IF(ISBLANK('02_Market_Inputs'!V5),50,MIN(100,MAX(0,50+'02_Market_Inputs'!V5*100))) | W5: =IF(ISBLANK('02_Market_Inputs'!Y5),50,MIN(100,MAX(0,50+'02_Market_Inputs'!Y5*15)))
A6: ='02_Market_Inputs'!A6 | B6: ='02_Market_Inputs'!B6 | C6: =IF(ISBLANK('02_Market_Inputs'!E6),50,MIN(100,MAX(0,100-('02_Market_Inputs'!E6-1)*14))) | D6: =IF(ISBLANK('02_Market_Inputs'!F6),50,MIN(100,MAX(0,50-'02_Market_Inputs'!F6*100))) | E6: =IF(ISBLANK('02_Market_Inputs'!I6),50,MIN(100,MAX(0,50-'02_Market_Inputs'!I6*15))) | F6: =IF(ISBLANK('02_Market_Inputs'!J6),50,MIN(100,MAX(0,80-ABS('02_Market_Inputs'!J6-12)*4))) | G6: =IF(OR(ISBLANK('02_Market_Inputs'!G6),ISBLANK('02_Market_Inputs'!H6)),50,(MIN(100,MAX(0,100-('02_Market_Inputs'!G6-2.5)*28.5))+MIN(100,MAX(0,('02_Market_Inputs'!H6+0.2)*58)))/2) | H6: =IF(ISBLANK('02_Market_Inputs'!K6),50,MIN(100,MAX(0,50-'02_Market_Inputs'!K6*20))) | I6: =IF(ISBLANK('02_Market_Inputs'!L6),50,MIN(100,MAX(0,100-'02_Market_Inputs'!L6*20))) | J6: =IF(ISBLANK('02_Market_Inputs'!M6),50,MIN(100,MAX(0,50+'02_Market_Inputs'!M6*15))) | K6: =IF(ISBLANK('02_Market_Inputs'!O6),50,MIN(100,MAX(0,50+'02_Market_Inputs'!O6*15))) | L6: =IF(OR(ISBLANK('02_Market_Inputs'!P6),'02_Market_Inputs'!P6<=0),50,MIN(100,MAX(0,100-'02_Market_Inputs'!P6))) | M6: =IF(ISBLANK('02_Market_Inputs'!Q6),50,MIN(100,MAX(0,50-'02_Market_Inputs'!Q6*25))) | N6: =IF(ISBLANK('02_Market_Inputs'!R6),50,MIN(100,MAX(0,50-'02_Market_Inputs'!R6*25))) | O6: =IF(ISBLANK('02_Market_Inputs'!S6),50,MIN(100,MAX(0,100-'02_Market_Inputs'!S6))) | P6: =IF(ISBLANK('02_Market_Inputs'!T6),50,MIN(100,MAX(0,50+'02_Market_Inputs'!T6*25))) | Q6: ='06_MLR_Regression'!H6 | R6: ='07_VAR_Granger'!K6 | S6: ='08_ML_Validation'!K6 | T6: ='08_ML_Validation'!L6 | U6: =IF('02_Market_Inputs'!W6="completed",85,IF('02_Market_Inputs'!W6="confirmed",75,IF('02_Market_Inputs'!W6="pending",55,50)))+IF('02_Market_Inputs'!X6<=1,20,IF('02_Market_Inputs'!X6<=2,12,IF('02_Market_Inputs'!X6<=3,6,0))) | V6: =IF(ISBLANK('02_Market_Inputs'!V6),50,MIN(100,MAX(0,50+'02_Market_Inputs'!V6*100))) | W6: =IF(ISBLANK('02_Market_Inputs'!Y6),50,MIN(100,MAX(0,50+'02_Market_Inputs'!Y6*15)))
A7: ='02_Market_Inputs'!A7 | B7: ='02_Market_Inputs'!B7 | C7: =IF(ISBLANK('02_Market_Inputs'!E7),50,MIN(100,MAX(0,100-('02_Market_Inputs'!E7-1)*14))) | D7: =IF(ISBLANK('02_Market_Inputs'!F7),50,MIN(100,MAX(0,50-'02_Market_Inputs'!F7*100))) | E7: =IF(ISBLANK('02_Market_Inputs'!I7),50,MIN(100,MAX(0,50-'02_Market_Inputs'!I7*15))) | F7: =IF(ISBLANK('02_Market_Inputs'!J7),50,MIN(100,MAX(0,80-ABS('02_Market_Inputs'!J7-12)*4))) | G7: =IF(OR(ISBLANK('02_Market_Inputs'!G7),ISBLANK('02_Market_Inputs'!H7)),50,(MIN(100,MAX(0,100-('02_Market_Inputs'!G7-2.5)*28.5))+MIN(100,MAX(0,('02_Market_Inputs'!H7+0.2)*58)))/2) | H7: =IF(ISBLANK('02_Market_Inputs'!K7),50,MIN(100,MAX(0,50-'02_Market_Inputs'!K7*20))) | I7: =IF(ISBLANK('02_Market_Inputs'!L7),50,MIN(100,MAX(0,100-'02_Market_Inputs'!L7*20))) | J7: =IF(ISBLANK('02_Market_Inputs'!M7),50,MIN(100,MAX(0,50+'02_Market_Inputs'!M7*15))) | K7: =IF(ISBLANK('02_Market_Inputs'!O7),50,MIN(100,MAX(0,50+'02_Market_Inputs'!O7*15))) | L7: =IF(OR(ISBLANK('02_Market_Inputs'!P7),'02_Market_Inputs'!P7<=0),50,MIN(100,MAX(0,100-'02_Market_Inputs'!P7))) | M7: =IF(ISBLANK('02_Market_Inputs'!Q7),50,MIN(100,MAX(0,50-'02_Market_Inputs'!Q7*25))) | N7: =IF(ISBLANK('02_Market_Inputs'!R7),50,MIN(100,MAX(0,50-'02_Market_Inputs'!R7*25))) | O7: =IF(ISBLANK('02_Market_Inputs'!S7),50,MIN(100,MAX(0,100-'02_Market_Inputs'!S7))) | P7: =IF(ISBLANK('02_Market_Inputs'!T7),50,MIN(100,MAX(0,50+'02_Market_Inputs'!T7*25))) | Q7: ='06_MLR_Regression'!H7 | R7: ='07_VAR_Granger'!K7 | S7: ='08_ML_Validation'!K7 | T7: ='08_ML_Validation'!L7 | U7: =IF('02_Market_Inputs'!W7="completed",85,IF('02_Market_Inputs'!W7="confirmed",75,IF('02_Market_Inputs'!W7="pending",55,50)))+IF('02_Market_Inputs'!X7<=1,20,IF('02_Market_Inputs'!X7<=2,12,IF('02_Market_Inputs'!X7<=3,6,0))) | V7: =IF(ISBLANK('02_Market_Inputs'!V7),50,MIN(100,MAX(0,50+'02_Market_Inputs'!V7*100))) | W7: =IF(ISBLANK('02_Market_Inputs'!Y7),50,MIN(100,MAX(0,50+'02_Market_Inputs'!Y7*15)))
A8: ='02_Market_Inputs'!A8 | B8: ='02_Market_Inputs'!B8 | C8: =IF(ISBLANK('02_Market_Inputs'!E8),50,MIN(100,MAX(0,100-('02_Market_Inputs'!E8-1)*14))) | D8: =IF(ISBLANK('02_Market_Inputs'!F8),50,MIN(100,MAX(0,50-'02_Market_Inputs'!F8*100))) | E8: =IF(ISBLANK('02_Market_Inputs'!I8),50,MIN(100,MAX(0,50-'02_Market_Inputs'!I8*15))) | F8: =IF(ISBLANK('02_Market_Inputs'!J8),50,MIN(100,MAX(0,80-ABS('02_Market_Inputs'!J8-12)*4))) | G8: =IF(OR(ISBLANK('02_Market_Inputs'!G8),ISBLANK('02_Market_Inputs'!H8)),50,(MIN(100,MAX(0,100-('02_Market_Inputs'!G8-2.5)*28.5))+MIN(100,MAX(0,('02_Market_Inputs'!H8+0.2)*58)))/2) | H8: =IF(ISBLANK('02_Market_Inputs'!K8),50,MIN(100,MAX(0,50-'02_Market_Inputs'!K8*20))) | I8: =IF(ISBLANK('02_Market_Inputs'!L8),50,MIN(100,MAX(0,100-'02_Market_Inputs'!L8*20))) | J8: =IF(ISBLANK('02_Market_Inputs'!M8),50,MIN(100,MAX(0,50+'02_Market_Inputs'!M8*15))) | K8: =IF(ISBLANK('02_Market_Inputs'!O8),50,MIN(100,MAX(0,50+'02_Market_Inputs'!O8*15))) | L8: =IF(OR(ISBLANK('02_Market_Inputs'!P8),'02_Market_Inputs'!P8<=0),50,MIN(100,MAX(0,100-'02_Market_Inputs'!P8))) | M8: =IF(ISBLANK('02_Market_Inputs'!Q8),50,MIN(100,MAX(0,50-'02_Market_Inputs'!Q8*25))) | N8: =IF(ISBLANK('02_Market_Inputs'!R8),50,MIN(100,MAX(0,50-'02_Market_Inputs'!R8*25))) | O8: =IF(ISBLANK('02_Market_Inputs'!S8),50,MIN(100,MAX(0,100-'02_Market_Inputs'!S8))) | P8: =IF(ISBLANK('02_Market_Inputs'!T8),50,MIN(100,MAX(0,50+'02_Market_Inputs'!T8*25))) | Q8: ='06_MLR_Regression'!H8 | R8: ='07_VAR_Granger'!K8 | S8: ='08_ML_Validation'!K8 | T8: ='08_ML_Validation'!L8 | U8: =IF('02_Market_Inputs'!W8="completed",85,IF('02_Market_Inputs'!W8="confirmed",75,IF('02_Market_Inputs'!W8="pending",55,50)))+IF('02_Market_Inputs'!X8<=1,20,IF('02_Market_Inputs'!X8<=2,12,IF('02_Market_Inputs'!X8<=3,6,0))) | V8: =IF(ISBLANK('02_Market_Inputs'!V8),50,MIN(100,MAX(0,50+'02_Market_Inputs'!V8*100))) | W8: =IF(ISBLANK('02_Market_Inputs'!Y8),50,MIN(100,MAX(0,50+'02_Market_Inputs'!Y8*15)))
A9: ='02_Market_Inputs'!A9 | B9: ='02_Market_Inputs'!B9 | C9: =IF(ISBLANK('02_Market_Inputs'!E9),50,MIN(100,MAX(0,100-('02_Market_Inputs'!E9-1)*14))) | D9: =IF(ISBLANK('02_Market_Inputs'!F9),50,MIN(100,MAX(0,50-'02_Market_Inputs'!F9*100))) | E9: =IF(ISBLANK('02_Market_Inputs'!I9),50,MIN(100,MAX(0,50-'02_Market_Inputs'!I9*15))) | F9: =IF(ISBLANK('02_Market_Inputs'!J9),50,MIN(100,MAX(0,80-ABS('02_Market_Inputs'!J9-12)*4))) | G9: =IF(OR(ISBLANK('02_Market_Inputs'!G9),ISBLANK('02_Market_Inputs'!H9)),50,(MIN(100,MAX(0,100-('02_Market_Inputs'!G9-2.5)*28.5))+MIN(100,MAX(0,('02_Market_Inputs'!H9+0.2)*58)))/2) | H9: =IF(ISBLANK('02_Market_Inputs'!K9),50,MIN(100,MAX(0,50-'02_Market_Inputs'!K9*20))) | I9: =IF(ISBLANK('02_Market_Inputs'!L9),50,MIN(100,MAX(0,100-'02_Market_Inputs'!L9*20))) | J9: =IF(ISBLANK('02_Market_Inputs'!M9),50,MIN(100,MAX(0,50+'02_Market_Inputs'!M9*15))) | K9: =IF(ISBLANK('02_Market_Inputs'!O9),50,MIN(100,MAX(0,50+'02_Market_Inputs'!O9*15))) | L9: =IF(OR(ISBLANK('02_Market_Inputs'!P9),'02_Market_Inputs'!P9<=0),50,MIN(100,MAX(0,100-'02_Market_Inputs'!P9))) | M9: =IF(ISBLANK('02_Market_Inputs'!Q9),50,MIN(100,MAX(0,50-'02_Market_Inputs'!Q9*25))) | N9: =IF(ISBLANK('02_Market_Inputs'!R9),50,MIN(100,MAX(0,50-'02_Market_Inputs'!R9*25))) | O9: =IF(ISBLANK('02_Market_Inputs'!S9),50,MIN(100,MAX(0,100-'02_Market_Inputs'!S9))) | P9: =IF(ISBLANK('02_Market_Inputs'!T9),50,MIN(100,MAX(0,50+'02_Market_Inputs'!T9*25))) | Q9: ='06_MLR_Regression'!H9 | R9: ='07_VAR_Granger'!K9 | S9: ='08_ML_Validation'!K9 | T9: ='08_ML_Validation'!L9 | U9: =IF('02_Market_Inputs'!W9="completed",85,IF('02_Market_Inputs'!W9="confirmed",75,IF('02_Market_Inputs'!W9="pending",55,50)))+IF('02_Market_Inputs'!X9<=1,20,IF('02_Market_Inputs'!X9<=2,12,IF('02_Market_Inputs'!X9<=3,6,0))) | V9: =IF(ISBLANK('02_Market_Inputs'!V9),50,MIN(100,MAX(0,50+'02_Market_Inputs'!V9*100))) | W9: =IF(ISBLANK('02_Market_Inputs'!Y9),50,MIN(100,MAX(0,50+'02_Market_Inputs'!Y9*15)))
A10: ='02_Market_Inputs'!A10 | B10: ='02_Market_Inputs'!B10 | C10: =IF(ISBLANK('02_Market_Inputs'!E10),50,MIN(100,MAX(0,100-('02_Market_Inputs'!E10-1)*14))) | D10: =IF(ISBLANK('02_Market_Inputs'!F10),50,MIN(100,MAX(0,50-'02_Market_Inputs'!F10*100))) | E10: =IF(ISBLANK('02_Market_Inputs'!I10),50,MIN(100,MAX(0,50-'02_Market_Inputs'!I10*15))) | F10: =IF(ISBLANK('02_Market_Inputs'!J10),50,MIN(100,MAX(0,80-ABS('02_Market_Inputs'!J10-12)*4))) | G10: =IF(OR(ISBLANK('02_Market_Inputs'!G10),ISBLANK('02_Market_Inputs'!H10)),50,(MIN(100,MAX(0,100-('02_Market_Inputs'!G10-2.5)*28.5))+MIN(100,MAX(0,('02_Market_Inputs'!H10+0.2)*58)))/2) | H10: =IF(ISBLANK('02_Market_Inputs'!K10),50,MIN(100,MAX(0,50-'02_Market_Inputs'!K10*20))) | I10: =IF(ISBLANK('02_Market_Inputs'!L10),50,MIN(100,MAX(0,100-'02_Market_Inputs'!L10*20))) | J10: =IF(ISBLANK('02_Market_Inputs'!M10),50,MIN(100,MAX(0,50+'02_Market_Inputs'!M10*15))) | K10: =IF(ISBLANK('02_Market_Inputs'!O10),50,MIN(100,MAX(0,50+'02_Market_Inputs'!O10*15))) | L10: =IF(OR(ISBLANK('02_Market_Inputs'!P10),'02_Market_Inputs'!P10<=0),50,MIN(100,MAX(0,100-'02_Market_Inputs'!P10))) | M10: =IF(ISBLANK('02_Market_Inputs'!Q10),50,MIN(100,MAX(0,50-'02_Market_Inputs'!Q10*25))) | N10: =IF(ISBLANK('02_Market_Inputs'!R10),50,MIN(100,MAX(0,50-'02_Market_Inputs'!R10*25))) | O10: =IF(ISBLANK('02_Market_Inputs'!S10),50,MIN(100,MAX(0,100-'02_Market_Inputs'!S10))) | P10: =IF(ISBLANK('02_Market_Inputs'!T10),50,MIN(100,MAX(0,50+'02_Market_Inputs'!T10*25))) | Q10: ='06_MLR_Regression'!H10 | R10: ='07_VAR_Granger'!K10 | S10: ='08_ML_Validation'!K10 | T10: ='08_ML_Validation'!L10 | U10: =IF('02_Market_Inputs'!W10="completed",85,IF('02_Market_Inputs'!W10="confirmed",75,IF('02_Market_Inputs'!W10="pending",55,50)))+IF('02_Market_Inputs'!X10<=1,20,IF('02_Market_Inputs'!X10<=2,12,IF('02_Market_Inputs'!X10<=3,6,0))) | V10: =IF(ISBLANK('02_Market_Inputs'!V10),50,MIN(100,MAX(0,50+'02_Market_Inputs'!V10*100))) | W10: =IF(ISBLANK('02_Market_Inputs'!Y10),50,MIN(100,MAX(0,50+'02_Market_Inputs'!Y10*15)))
A11: ='02_Market_Inputs'!A11 | B11: ='02_Market_Inputs'!B11 | C11: =IF(ISBLANK('02_Market_Inputs'!E11),50,MIN(100,MAX(0,100-('02_Market_Inputs'!E11-1)*14))) | D11: =IF(ISBLANK('02_Market_Inputs'!F11),50,MIN(100,MAX(0,50-'02_Market_Inputs'!F11*100))) | E11: =IF(ISBLANK('02_Market_Inputs'!I11),50,MIN(100,MAX(0,50-'02_Market_Inputs'!I11*15))) | F11: =IF(ISBLANK('02_Market_Inputs'!J11),50,MIN(100,MAX(0,80-ABS('02_Market_Inputs'!J11-12)*4))) | G11: =IF(OR(ISBLANK('02_Market_Inputs'!G11),ISBLANK('02_Market_Inputs'!H11)),50,(MIN(100,MAX(0,100-('02_Market_Inputs'!G11-2.5)*28.5))+MIN(100,MAX(0,('02_Market_Inputs'!H11+0.2)*58)))/2) | H11: =IF(ISBLANK('02_Market_Inputs'!K11),50,MIN(100,MAX(0,50-'02_Market_Inputs'!K11*20))) | I11: =IF(ISBLANK('02_Market_Inputs'!L11),50,MIN(100,MAX(0,100-'02_Market_Inputs'!L11*20))) | J11: =IF(ISBLANK('02_Market_Inputs'!M11),50,MIN(100,MAX(0,50+'02_Market_Inputs'!M11*15))) | K11: =IF(ISBLANK('02_Market_Inputs'!O11),50,MIN(100,MAX(0,50+'02_Market_Inputs'!O11*15))) | L11: =IF(OR(ISBLANK('02_Market_Inputs'!P11),'02_Market_Inputs'!P11<=0),50,MIN(100,MAX(0,100-'02_Market_Inputs'!P11))) | M11: =IF(ISBLANK('02_Market_Inputs'!Q11),50,MIN(100,MAX(0,50-'02_Market_Inputs'!Q11*25))) | N11: =IF(ISBLANK('02_Market_Inputs'!R11),50,MIN(100,MAX(0,50-'02_Market_Inputs'!R11*25))) | O11: =IF(ISBLANK('02_Market_Inputs'!S11),50,MIN(100,MAX(0,100-'02_Market_Inputs'!S11))) | P11: =IF(ISBLANK('02_Market_Inputs'!T11),50,MIN(100,MAX(0,50+'02_Market_Inputs'!T11*25))) | Q11: ='06_MLR_Regression'!H11 | R11: ='07_VAR_Granger'!K11 | S11: ='08_ML_Validation'!K11 | T11: ='08_ML_Validation'!L11 | U11: =IF('02_Market_Inputs'!W11="completed",85,IF('02_Market_Inputs'!W11="confirmed",75,IF('02_Market_Inputs'!W11="pending",55,50)))+IF('02_Market_Inputs'!X11<=1,20,IF('02_Market_Inputs'!X11<=2,12,IF('02_Market_Inputs'!X11<=3,6,0))) | V11: =IF(ISBLANK('02_Market_Inputs'!V11),50,MIN(100,MAX(0,50+'02_Market_Inputs'!V11*100))) | W11: =IF(ISBLANK('02_Market_Inputs'!Y11),50,MIN(100,MAX(0,50+'02_Market_Inputs'!Y11*15)))
A12: ='02_Market_Inputs'!A12 | B12: ='02_Market_Inputs'!B12 | C12: =IF(ISBLANK('02_Market_Inputs'!E12),50,MIN(100,MAX(0,100-('02_Market_Inputs'!E12-1)*14))) | D12: =IF(ISBLANK('02_Market_Inputs'!F12),50,MIN(100,MAX(0,50-'02_Market_Inputs'!F12*100))) | E12: =IF(ISBLANK('02_Market_Inputs'!I12),50,MIN(100,MAX(0,50-'02_Market_Inputs'!I12*15))) | F12: =IF(ISBLANK('02_Market_Inputs'!J12),50,MIN(100,MAX(0,80-ABS('02_Market_Inputs'!J12-12)*4))) | G12: =IF(OR(ISBLANK('02_Market_Inputs'!G12),ISBLANK('02_Market_Inputs'!H12)),50,(MIN(100,MAX(0,100-('02_Market_Inputs'!G12-2.5)*28.5))+MIN(100,MAX(0,('02_Market_Inputs'!H12+0.2)*58)))/2) | H12: =IF(ISBLANK('02_Market_Inputs'!K12),50,MIN(100,MAX(0,50-'02_Market_Inputs'!K12*20))) | I12: =IF(ISBLANK('02_Market_Inputs'!L12),50,MIN(100,MAX(0,100-'02_Market_Inputs'!L12*20))) | J12: =IF(ISBLANK('02_Market_Inputs'!M12),50,MIN(100,MAX(0,50+'02_Market_Inputs'!M12*15))) | K12: =IF(ISBLANK('02_Market_Inputs'!O12),50,MIN(100,MAX(0,50+'02_Market_Inputs'!O12*15))) | L12: =IF(OR(ISBLANK('02_Market_Inputs'!P12),'02_Market_Inputs'!P12<=0),50,MIN(100,MAX(0,100-'02_Market_Inputs'!P12))) | M12: =IF(ISBLANK('02_Market_Inputs'!Q12),50,MIN(100,MAX(0,50-'02_Market_Inputs'!Q12*25))) | N12: =IF(ISBLANK('02_Market_Inputs'!R12),50,MIN(100,MAX(0,50-'02_Market_Inputs'!R12*25))) | O12: =IF(ISBLANK('02_Market_Inputs'!S12),50,MIN(100,MAX(0,100-'02_Market_Inputs'!S12))) | P12: =IF(ISBLANK('02_Market_Inputs'!T12),50,MIN(100,MAX(0,50+'02_Market_Inputs'!T12*25))) | Q12: ='06_MLR_Regression'!H12 | R12: ='07_VAR_Granger'!K12 | S12: ='08_ML_Validation'!K12 | T12: ='08_ML_Validation'!L12 | U12: =IF('02_Market_Inputs'!W12="completed",85,IF('02_Market_Inputs'!W12="confirmed",75,IF('02_Market_Inputs'!W12="pending",55,50)))+IF('02_Market_Inputs'!X12<=1,20,IF('02_Market_Inputs'!X12<=2,12,IF('02_Market_Inputs'!X12<=3,6,0))) | V12: =IF(ISBLANK('02_Market_Inputs'!V12),50,MIN(100,MAX(0,50+'02_Market_Inputs'!V12*100))) | W12: =IF(ISBLANK('02_Market_Inputs'!Y12),50,MIN(100,MAX(0,50+'02_Market_Inputs'!Y12*15)))
A13: ='02_Market_Inputs'!A13 | B13: ='02_Market_Inputs'!B13 | C13: =IF(ISBLANK('02_Market_Inputs'!E13),50,MIN(100,MAX(0,100-('02_Market_Inputs'!E13-1)*14))) | D13: =IF(ISBLANK('02_Market_Inputs'!F13),50,MIN(100,MAX(0,50-'02_Market_Inputs'!F13*100))) | E13: =IF(ISBLANK('02_Market_Inputs'!I13),50,MIN(100,MAX(0,50-'02_Market_Inputs'!I13*15))) | F13: =IF(ISBLANK('02_Market_Inputs'!J13),50,MIN(100,MAX(0,80-ABS('02_Market_Inputs'!J13-12)*4))) | G13: =IF(OR(ISBLANK('02_Market_Inputs'!G13),ISBLANK('02_Market_Inputs'!H13)),50,(MIN(100,MAX(0,100-('02_Market_Inputs'!G13-2.5)*28.5))+MIN(100,MAX(0,('02_Market_Inputs'!H13+0.2)*58)))/2) | H13: =IF(ISBLANK('02_Market_Inputs'!K13),50,MIN(100,MAX(0,50-'02_Market_Inputs'!K13*20))) | I13: =IF(ISBLANK('02_Market_Inputs'!L13),50,MIN(100,MAX(0,100-'02_Market_Inputs'!L13*20))) | J13: =IF(ISBLANK('02_Market_Inputs'!M13),50,MIN(100,MAX(0,50+'02_Market_Inputs'!M13*15))) | K13: =IF(ISBLANK('02_Market_Inputs'!O13),50,MIN(100,MAX(0,50+'02_Market_Inputs'!O13*15))) | L13: =IF(OR(ISBLANK('02_Market_Inputs'!P13),'02_Market_Inputs'!P13<=0),50,MIN(100,MAX(0,100-'02_Market_Inputs'!P13))) | M13: =IF(ISBLANK('02_Market_Inputs'!Q13),50,MIN(100,MAX(0,50-'02_Market_Inputs'!Q13*25))) | N13: =IF(ISBLANK('02_Market_Inputs'!R13),50,MIN(100,MAX(0,50-'02_Market_Inputs'!R13*25))) | O13: =IF(ISBLANK('02_Market_Inputs'!S13),50,MIN(100,MAX(0,100-'02_Market_Inputs'!S13))) | P13: =IF(ISBLANK('02_Market_Inputs'!T13),50,MIN(100,MAX(0,50+'02_Market_Inputs'!T13*25))) | Q13: ='06_MLR_Regression'!H13 | R13: ='07_VAR_Granger'!K13 | S13: ='08_ML_Validation'!K13 | T13: ='08_ML_Validation'!L13 | U13: =IF('02_Market_Inputs'!W13="completed",85,IF('02_Market_Inputs'!W13="confirmed",75,IF('02_Market_Inputs'!W13="pending",55,50)))+IF('02_Market_Inputs'!X13<=1,20,IF('02_Market_Inputs'!X13<=2,12,IF('02_Market_Inputs'!X13<=3,6,0))) | V13: =IF(ISBLANK('02_Market_Inputs'!V13),50,MIN(100,MAX(0,50+'02_Market_Inputs'!V13*100))) | W13: =IF(ISBLANK('02_Market_Inputs'!Y13),50,MIN(100,MAX(0,50+'02_Market_Inputs'!Y13*15)))
A14: ='02_Market_Inputs'!A14 | B14: ='02_Market_Inputs'!B14 | C14: =IF(ISBLANK('02_Market_Inputs'!E14),50,MIN(100,MAX(0,100-('02_Market_Inputs'!E14-1)*14))) | D14: =IF(ISBLANK('02_Market_Inputs'!F14),50,MIN(100,MAX(0,50-'02_Market_Inputs'!F14*100))) | E14: =IF(ISBLANK('02_Market_Inputs'!I14),50,MIN(100,MAX(0,50-'02_Market_Inputs'!I14*15))) | F14: =IF(ISBLANK('02_Market_Inputs'!J14),50,MIN(100,MAX(0,80-ABS('02_Market_Inputs'!J14-12)*4))) | G14: =IF(OR(ISBLANK('02_Market_Inputs'!G14),ISBLANK('02_Market_Inputs'!H14)),50,(MIN(100,MAX(0,100-('02_Market_Inputs'!G14-2.5)*28.5))+MIN(100,MAX(0,('02_Market_Inputs'!H14+0.2)*58)))/2) | H14: =IF(ISBLANK('02_Market_Inputs'!K14),50,MIN(100,MAX(0,50-'02_Market_Inputs'!K14*20))) | I14: =IF(ISBLANK('02_Market_Inputs'!L14),50,MIN(100,MAX(0,100-'02_Market_Inputs'!L14*20))) | J14: =IF(ISBLANK('02_Market_Inputs'!M14),50,MIN(100,MAX(0,50+'02_Market_Inputs'!M14*15))) | K14: =IF(ISBLANK('02_Market_Inputs'!O14),50,MIN(100,MAX(0,50+'02_Market_Inputs'!O14*15))) | L14: =IF(OR(ISBLANK('02_Market_Inputs'!P14),'02_Market_Inputs'!P14<=0),50,MIN(100,MAX(0,100-'02_Market_Inputs'!P14))) | M14: =IF(ISBLANK('02_Market_Inputs'!Q14),50,MIN(100,MAX(0,50-'02_Market_Inputs'!Q14*25))) | N14: =IF(ISBLANK('02_Market_Inputs'!R14),50,MIN(100,MAX(0,50-'02_Market_Inputs'!R14*25))) | O14: =IF(ISBLANK('02_Market_Inputs'!S14),50,MIN(100,MAX(0,100-'02_Market_Inputs'!S14))) | P14: =IF(ISBLANK('02_Market_Inputs'!T14),50,MIN(100,MAX(0,50+'02_Market_Inputs'!T14*25))) | Q14: ='06_MLR_Regression'!H14 | R14: ='07_VAR_Granger'!K14 | S14: ='08_ML_Validation'!K14 | T14: ='08_ML_Validation'!L14 | U14: =IF('02_Market_Inputs'!W14="completed",85,IF('02_Market_Inputs'!W14="confirmed",75,IF('02_Market_Inputs'!W14="pending",55,50)))+IF('02_Market_Inputs'!X14<=1,20,IF('02_Market_Inputs'!X14<=2,12,IF('02_Market_Inputs'!X14<=3,6,0))) | V14: =IF(ISBLANK('02_Market_Inputs'!V14),50,MIN(100,MAX(0,50+'02_Market_Inputs'!V14*100))) | W14: =IF(ISBLANK('02_Market_Inputs'!Y14),50,MIN(100,MAX(0,50+'02_Market_Inputs'!Y14*15)))
A15: ='02_Market_Inputs'!A15 | B15: ='02_Market_Inputs'!B15 | C15: =IF(ISBLANK('02_Market_Inputs'!E15),50,MIN(100,MAX(0,100-('02_Market_Inputs'!E15-1)*14))) | D15: =IF(ISBLANK('02_Market_Inputs'!F15),50,MIN(100,MAX(0,50-'02_Market_Inputs'!F15*100))) | E15: =IF(ISBLANK('02_Market_Inputs'!I15),50,MIN(100,MAX(0,50-'02_Market_Inputs'!I15*15))) | F15: =IF(ISBLANK('02_Market_Inputs'!J15),50,MIN(100,MAX(0,80-ABS('02_Market_Inputs'!J15-12)*4))) | G15: =IF(OR(ISBLANK('02_Market_Inputs'!G15),ISBLANK('02_Market_Inputs'!H15)),50,(MIN(100,MAX(0,100-('02_Market_Inputs'!G15-2.5)*28.5))+MIN(100,MAX(0,('02_Market_Inputs'!H15+0.2)*58)))/2) | H15: =IF(ISBLANK('02_Market_Inputs'!K15),50,MIN(100,MAX(0,50-'02_Market_Inputs'!K15*20))) | I15: =IF(ISBLANK('02_Market_Inputs'!L15),50,MIN(100,MAX(0,100-'02_Market_Inputs'!L15*20))) | J15: =IF(ISBLANK('02_Market_Inputs'!M15),50,MIN(100,MAX(0,50+'02_Market_Inputs'!M15*15))) | K15: =IF(ISBLANK('02_Market_Inputs'!O15),50,MIN(100,MAX(0,50+'02_Market_Inputs'!O15*15))) | L15: =IF(OR(ISBLANK('02_Market_Inputs'!P15),'02_Market_Inputs'!P15<=0),50,MIN(100,MAX(0,100-'02_Market_Inputs'!P15))) | M15: =IF(ISBLANK('02_Market_Inputs'!Q15),50,MIN(100,MAX(0,50-'02_Market_Inputs'!Q15*25))) | N15: =IF(ISBLANK('02_Market_Inputs'!R15),50,MIN(100,MAX(0,50-'02_Market_Inputs'!R15*25))) | O15: =IF(ISBLANK('02_Market_Inputs'!S15),50,MIN(100,MAX(0,100-'02_Market_Inputs'!S15))) | P15: =IF(ISBLANK('02_Market_Inputs'!T15),50,MIN(100,MAX(0,50+'02_Market_Inputs'!T15*25))) | Q15: ='06_MLR_Regression'!H15 | R15: ='07_VAR_Granger'!K15 | S15: ='08_ML_Validation'!K15 | T15: ='08_ML_Validation'!L15 | U15: =IF('02_Market_Inputs'!W15="completed",85,IF('02_Market_Inputs'!W15="confirmed",75,IF('02_Market_Inputs'!W15="pending",55,50)))+IF('02_Market_Inputs'!X15<=1,20,IF('02_Market_Inputs'!X15<=2,12,IF('02_Market_Inputs'!X15<=3,6,0))) | V15: =IF(ISBLANK('02_Market_Inputs'!V15),50,MIN(100,MAX(0,50+'02_Market_Inputs'!V15*100))) | W15: =IF(ISBLANK('02_Market_Inputs'!Y15),50,MIN(100,MAX(0,50+'02_Market_Inputs'!Y15*15)))
A16: ='02_Market_Inputs'!A16 | B16: ='02_Market_Inputs'!B16 | C16: =IF(ISBLANK('02_Market_Inputs'!E16),50,MIN(100,MAX(0,100-('02_Market_Inputs'!E16-1)*14))) | D16: =IF(ISBLANK('02_Market_Inputs'!F16),50,MIN(100,MAX(0,50-'02_Market_Inputs'!F16*100))) | E16: =IF(ISBLANK('02_Market_Inputs'!I16),50,MIN(100,MAX(0,50-'02_Market_Inputs'!I16*15))) | F16: =IF(ISBLANK('02_Market_Inputs'!J16),50,MIN(100,MAX(0,80-ABS('02_Market_Inputs'!J16-12)*4))) | G16: =IF(OR(ISBLANK('02_Market_Inputs'!G16),ISBLANK('02_Market_Inputs'!H16)),50,(MIN(100,MAX(0,100-('02_Market_Inputs'!G16-2.5)*28.5))+MIN(100,MAX(0,('02_Market_Inputs'!H16+0.2)*58)))/2) | H16: =IF(ISBLANK('02_Market_Inputs'!K16),50,MIN(100,MAX(0,50-'02_Market_Inputs'!K16*20))) | I16: =IF(ISBLANK('02_Market_Inputs'!L16),50,MIN(100,MAX(0,100-'02_Market_Inputs'!L16*20))) | J16: =IF(ISBLANK('02_Market_Inputs'!M16),50,MIN(100,MAX(0,50+'02_Market_Inputs'!M16*15))) | K16: =IF(ISBLANK('02_Market_Inputs'!O16),50,MIN(100,MAX(0,50+'02_Market_Inputs'!O16*15))) | L16: =IF(OR(ISBLANK('02_Market_Inputs'!P16),'02_Market_Inputs'!P16<=0),50,MIN(100,MAX(0,100-'02_Market_Inputs'!P16))) | M16: =IF(ISBLANK('02_Market_Inputs'!Q16),50,MIN(100,MAX(0,50-'02_Market_Inputs'!Q16*25))) | N16: =IF(ISBLANK('02_Market_Inputs'!R16),50,MIN(100,MAX(0,50-'02_Market_Inputs'!R16*25))) | O16: =IF(ISBLANK('02_Market_Inputs'!S16),50,MIN(100,MAX(0,100-'02_Market_Inputs'!S16))) | P16: =IF(ISBLANK('02_Market_Inputs'!T16),50,MIN(100,MAX(0,50+'02_Market_Inputs'!T16*25))) | Q16: ='06_MLR_Regression'!H16 | R16: ='07_VAR_Granger'!K16 | S16: ='08_ML_Validation'!K16 | T16: ='08_ML_Validation'!L16 | U16: =IF('02_Market_Inputs'!W16="completed",85,IF('02_Market_Inputs'!W16="confirmed",75,IF('02_Market_Inputs'!W16="pending",55,50)))+IF('02_Market_Inputs'!X16<=1,20,IF('02_Market_Inputs'!X16<=2,12,IF('02_Market_Inputs'!X16<=3,6,0))) | V16: =IF(ISBLANK('02_Market_Inputs'!V16),50,MIN(100,MAX(0,50+'02_Market_Inputs'!V16*100))) | W16: =IF(ISBLANK('02_Market_Inputs'!Y16),50,MIN(100,MAX(0,50+'02_Market_Inputs'!Y16*15)))
... A28: ='02_Market_Inputs'!A28 | B28: ='02_Market_Inputs'!B28 | C28: =IF(ISBLANK('02_Market_Inputs'!E28),50,MIN(100,MAX(0,100-('02_Market_Inputs'!E28-1)*14))) | D28: =IF(ISBLANK('02_Market_Inputs'!F28),50,MIN(100,MAX(0,50-'02_Market_Inputs'!F28*100))) | E28: =IF(ISBLANK('02_Market_Inputs'!I28),50,MIN(100,MAX(0,50-'02_Market_Inputs'!I28*15))) | F28: =IF(ISBLANK('02_Market_Inputs'!J28),50,MIN(100,MAX(0,80-ABS('02_Market_Inputs'!J28-12)*4))) | G28: =IF(OR(ISBLANK('02_Market_Inputs'!G28),ISBLANK('02_Market_Inputs'!H28)),50,(MIN(100,MAX(0,100-('02_Market_Inputs'!G28-2.5)*28.5))+MIN(100,MAX(0,('02_Market_Inputs'!H28+0.2)*58)))/2) | H28: =IF(ISBLANK('02_Market_Inputs'!K28),50,MIN(100,MAX(0,50-'02_Market_Inputs'!K28*20))) | I28: =IF(ISBLANK('02_Market_Inputs'!L28),50,MIN(100,MAX(0,100-'02_Market_Inputs'!L28*20))) | J28: =IF(ISBLANK('02_Market_Inputs'!M28),50,MIN(100,MAX(0,50+'02_Market_Inputs'!M28*15))) | K28: =IF(ISBLANK('02_Market_Inputs'!O28),50,MIN(100,MAX(0,50+'02_Market_Inputs'!O28*15))) | L28: =IF(OR(ISBLANK('02_Market_Inputs'!P28),'02_Market_Inputs'!P28<=0),50,MIN(100,MAX(0,100-'02_Market_Inputs'!P28))) | M28: =IF(ISBLANK('02_Market_Inputs'!Q28),50,MIN(100,MAX(0,50-'02_Market_Inputs'!Q28*25))) | N28: =IF(ISBLANK('02_Market_Inputs'!R28),50,MIN(100,MAX(0,50-'02_Market_Inputs'!R28*25))) | O28: =IF(ISBLANK('02_Market_Inputs'!S28),50,MIN(100,MAX(0,100-'02_Market_Inputs'!S28))) | P28: =IF(ISBLANK('02_Market_Inputs'!T28),50,MIN(100,MAX(0,50+'02_Market_Inputs'!T28*25))) | Q28: ='06_MLR_Regression'!H28 | R28: ='07_VAR_Granger'!K28 | S28: ='08_ML_Validation'!K28 | T28: ='08_ML_Validation'!L28 | U28: =IF('02_Market_Inputs'!W28="completed",85,IF('02_Market_Inputs'!W28="confirmed",75,IF('02_Market_Inputs'!W28="pending",55,50)))+IF('02_Market_Inputs'!X28<=1,20,IF('02_Market_Inputs'!X28<=2,12,IF('02_Market_Inputs'!X28<=3,6,0))) | V28: =IF(ISBLANK('02_Market_Inputs'!V28),50,MIN(100,MAX(0,50+'02_Market_Inputs'!V28*100))) | W28: =IF(ISBLANK('02_Market_Inputs'!Y28),50,MIN(100,MAX(0,50+'02_Market_Inputs'!Y28*15)))

Sheet 04_Pillar_Calculation
A1: SIX-PILLAR FORMULA CALCULATION
A2: Raw scores are rounded exactly as the production scorer, weighted contributions are rounded before summation
A4: Quarter | B4: As-of Date | C4: Macro Raw | D4: Global Raw | E4: Valuation Raw | F4: Quant Raw | G4: ML Raw | H4: Market Structure Raw | I4: Macro Weighted | J4: Global Weighted | K4: Valuation Weighted | L4: Quant Weighted | M4: ML Weighted | N4: Market Weighted | O4: Raw Composite | P4: Macro Unrounded | Q4: Global Unrounded | R4: Valuation Unrounded | S4: Quant Unrounded | T4: ML Unrounded | U4: Market Unrounded
A5: ='03_Factor_SubScores'!A5 | B5: ='03_Factor_SubScores'!B5 | C5: =ROUND(P5,2) | D5: =ROUND(Q5,2) | E5: =ROUND(R5,2) | F5: =ROUND(S5,2) | G5: =ROUND(T5,2) | H5: =ROUND(U5,2) | I5: =ROUND(P5*'01_Model_Config'!$C$6,2) | J5: =ROUND(Q5*'01_Model_Config'!$C$7,2) | K5: =ROUND(R5*'01_Model_Config'!$C$8,2) | L5: =ROUND(S5*'01_Model_Config'!$C$9,2) | M5: =ROUND(T5*'01_Model_Config'!$C$10,2) | N5: =ROUND(U5*'01_Model_Config'!$C$11,2) | O5: =SUM(I5:N5) | P5: =AVERAGE('03_Factor_SubScores'!C5:G5) | Q5: =IF('02_Market_Inputs'!O5<-2,MIN(20,IF('02_Market_Inputs'!P5>0,AVERAGE('03_Factor_SubScores'!H5:L5),AVERAGE('03_Factor_SubScores'!H5:K5))),IF('02_Market_Inputs'!P5>0,AVERAGE('03_Factor_SubScores'!H5:L5),AVERAGE('03_Factor_SubScores'!H5:K5))) | R5: =IF(ISBLANK('02_Market_Inputs'!U5),AVERAGE('03_Factor_SubScores'!M5:P5),AVERAGE('03_Factor_SubScores'!M5:P5)*0.7+'02_Market_Inputs'!U5*0.3) | S5: =MIN(100,MAX(0,AVERAGE('03_Factor_SubScores'!Q5:R5)+MIN(10,'06_MLR_Regression'!G5)+MIN(15,'07_VAR_Granger'!I5*3))) | T5: =MIN(100,MAX(0,'03_Factor_SubScores'!S5*0.3+'03_Factor_SubScores'!T5*0.7)) | U5: =MIN(100,MAX(0,AVERAGE('03_Factor_SubScores'!U5:W5)))
A6: ='03_Factor_SubScores'!A6 | B6: ='03_Factor_SubScores'!B6 | C6: =ROUND(P6,2) | D6: =ROUND(Q6,2) | E6: =ROUND(R6,2) | F6: =ROUND(S6,2) | G6: =ROUND(T6,2) | H6: =ROUND(U6,2) | I6: =ROUND(P6*'01_Model_Config'!$C$6,2) | J6: =ROUND(Q6*'01_Model_Config'!$C$7,2) | K6: =ROUND(R6*'01_Model_Config'!$C$8,2) | L6: =ROUND(S6*'01_Model_Config'!$C$9,2) | M6: =ROUND(T6*'01_Model_Config'!$C$10,2) | N6: =ROUND(U6*'01_Model_Config'!$C$11,2) | O6: =SUM(I6:N6) | P6: =AVERAGE('03_Factor_SubScores'!C6:G6) | Q6: =IF('02_Market_Inputs'!O6<-2,MIN(20,IF('02_Market_Inputs'!P6>0,AVERAGE('03_Factor_SubScores'!H6:L6),AVERAGE('03_Factor_SubScores'!H6:K6))),IF('02_Market_Inputs'!P6>0,AVERAGE('03_Factor_SubScores'!H6:L6),AVERAGE('03_Factor_SubScores'!H6:K6))) | R6: =IF(ISBLANK('02_Market_Inputs'!U6),AVERAGE('03_Factor_SubScores'!M6:P6),AVERAGE('03_Factor_SubScores'!M6:P6)*0.7+'02_Market_Inputs'!U6*0.3) | S6: =MIN(100,MAX(0,AVERAGE('03_Factor_SubScores'!Q6:R6)+MIN(10,'06_MLR_Regression'!G6)+MIN(15,'07_VAR_Granger'!I6*3))) | T6: =MIN(100,MAX(0,'03_Factor_SubScores'!S6*0.3+'03_Factor_SubScores'!T6*0.7)) | U6: =MIN(100,MAX(0,AVERAGE('03_Factor_SubScores'!U6:W6)))
A7: ='03_Factor_SubScores'!A7 | B7: ='03_Factor_SubScores'!B7 | C7: =ROUND(P7,2) | D7: =ROUND(Q7,2) | E7: =ROUND(R7,2) | F7: =ROUND(S7,2) | G7: =ROUND(T7,2) | H7: =ROUND(U7,2) | I7: =ROUND(P7*'01_Model_Config'!$C$6,2) | J7: =ROUND(Q7*'01_Model_Config'!$C$7,2) | K7: =ROUND(R7*'01_Model_Config'!$C$8,2) | L7: =ROUND(S7*'01_Model_Config'!$C$9,2) | M7: =ROUND(T7*'01_Model_Config'!$C$10,2) | N7: =ROUND(U7*'01_Model_Config'!$C$11,2) | O7: =SUM(I7:N7) | P7: =AVERAGE('03_Factor_SubScores'!C7:G7) | Q7: =IF('02_Market_Inputs'!O7<-2,MIN(20,IF('02_Market_Inputs'!P7>0,AVERAGE('03_Factor_SubScores'!H7:L7),AVERAGE('03_Factor_SubScores'!H7:K7))),IF('02_Market_Inputs'!P7>0,AVERAGE('03_Factor_SubScores'!H7:L7),AVERAGE('03_Factor_SubScores'!H7:K7))) | R7: =IF(ISBLANK('02_Market_Inputs'!U7),AVERAGE('03_Factor_SubScores'!M7:P7),AVERAGE('03_Factor_SubScores'!M7:P7)*0.7+'02_Market_Inputs'!U7*0.3) | S7: =MIN(100,MAX(0,AVERAGE('03_Factor_SubScores'!Q7:R7)+MIN(10,'06_MLR_Regression'!G7)+MIN(15,'07_VAR_Granger'!I7*3))) | T7: =MIN(100,MAX(0,'03_Factor_SubScores'!S7*0.3+'03_Factor_SubScores'!T7*0.7)) | U7: =MIN(100,MAX(0,AVERAGE('03_Factor_SubScores'!U7:W7)))
A8: ='03_Factor_SubScores'!A8 | B8: ='03_Factor_SubScores'!B8 | C8: =ROUND(P8,2) | D8: =ROUND(Q8,2) | E8: =ROUND(R8,2) | F8: =ROUND(S8,2) | G8: =ROUND(T8,2) | H8: =ROUND(U8,2) | I8: =ROUND(P8*'01_Model_Config'!$C$6,2) | J8: =ROUND(Q8*'01_Model_Config'!$C$7,2) | K8: =ROUND(R8*'01_Model_Config'!$C$8,2) | L8: =ROUND(S8*'01_Model_Config'!$C$9,2) | M8: =ROUND(T8*'01_Model_Config'!$C$10,2) | N8: =ROUND(U8*'01_Model_Config'!$C$11,2) | O8: =SUM(I8:N8) | P8: =AVERAGE('03_Factor_SubScores'!C8:G8) | Q8: =IF('02_Market_Inputs'!O8<-2,MIN(20,IF('02_Market_Inputs'!P8>0,AVERAGE('03_Factor_SubScores'!H8:L8),AVERAGE('03_Factor_SubScores'!H8:K8))),IF('02_Market_Inputs'!P8>0,AVERAGE('03_Factor_SubScores'!H8:L8),AVERAGE('03_Factor_SubScores'!H8:K8))) | R8: =IF(ISBLANK('02_Market_Inputs'!U8),AVERAGE('03_Factor_SubScores'!M8:P8),AVERAGE('03_Factor_SubScores'!M8:P8)*0.7+'02_Market_Inputs'!U8*0.3) | S8: =MIN(100,MAX(0,AVERAGE('03_Factor_SubScores'!Q8:R8)+MIN(10,'06_MLR_Regression'!G8)+MIN(15,'07_VAR_Granger'!I8*3))) | T8: =MIN(100,MAX(0,'03_Factor_SubScores'!S8*0.3+'03_Factor_SubScores'!T8*0.7)) | U8: =MIN(100,MAX(0,AVERAGE('03_Factor_SubScores'!U8:W8)))
A9: ='03_Factor_SubScores'!A9 | B9: ='03_Factor_SubScores'!B9 | C9: =ROUND(P9,2) | D9: =ROUND(Q9,2) | E9: =ROUND(R9,2) | F9: =ROUND(S9,2) | G9: =ROUND(T9,2) | H9: =ROUND(U9,2) | I9: =ROUND(P9*'01_Model_Config'!$C$6,2) | J9: =ROUND(Q9*'01_Model_Config'!$C$7,2) | K9: =ROUND(R9*'01_Model_Config'!$C$8,2) | L9: =ROUND(S9*'01_Model_Config'!$C$9,2) | M9: =ROUND(T9*'01_Model_Config'!$C$10,2) | N9: =ROUND(U9*'01_Model_Config'!$C$11,2) | O9: =SUM(I9:N9) | P9: =AVERAGE('03_Factor_SubScores'!C9:G9) | Q9: =IF('02_Market_Inputs'!O9<-2,MIN(20,IF('02_Market_Inputs'!P9>0,AVERAGE('03_Factor_SubScores'!H9:L9),AVERAGE('03_Factor_SubScores'!H9:K9))),IF('02_Market_Inputs'!P9>0,AVERAGE('03_Factor_SubScores'!H9:L9),AVERAGE('03_Factor_SubScores'!H9:K9))) | R9: =IF(ISBLANK('02_Market_Inputs'!U9),AVERAGE('03_Factor_SubScores'!M9:P9),AVERAGE('03_Factor_SubScores'!M9:P9)*0.7+'02_Market_Inputs'!U9*0.3) | S9: =MIN(100,MAX(0,AVERAGE('03_Factor_SubScores'!Q9:R9)+MIN(10,'06_MLR_Regression'!G9)+MIN(15,'07_VAR_Granger'!I9*3))) | T9: =MIN(100,MAX(0,'03_Factor_SubScores'!S9*0.3+'03_Factor_SubScores'!T9*0.7)) | U9: =MIN(100,MAX(0,AVERAGE('03_Factor_SubScores'!U9:W9)))
A10: ='03_Factor_SubScores'!A10 | B10: ='03_Factor_SubScores'!B10 | C10: =ROUND(P10,2) | D10: =ROUND(Q10,2) | E10: =ROUND(R10,2) | F10: =ROUND(S10,2) | G10: =ROUND(T10,2) | H10: =ROUND(U10,2) | I10: =ROUND(P10*'01_Model_Config'!$C$6,2) | J10: =ROUND(Q10*'01_Model_Config'!$C$7,2) | K10: =ROUND(R10*'01_Model_Config'!$C$8,2) | L10: =ROUND(S10*'01_Model_Config'!$C$9,2) | M10: =ROUND(T10*'01_Model_Config'!$C$10,2) | N10: =ROUND(U10*'01_Model_Config'!$C$11,2) | O10: =SUM(I10:N10) | P10: =AVERAGE('03_Factor_SubScores'!C10:G10) | Q10: =IF('02_Market_Inputs'!O10<-2,MIN(20,IF('02_Market_Inputs'!P10>0,AVERAGE('03_Factor_SubScores'!H10:L10),AVERAGE('03_Factor_SubScores'!H10:K10))),IF('02_Market_Inputs'!P10>0,AVERAGE('03_Factor_SubScores'!H10:L10),AVERAGE('03_Factor_SubScores'!H10:K10))) | R10: =IF(ISBLANK('02_Market_Inputs'!U10),AVERAGE('03_Factor_SubScores'!M10:P10),AVERAGE('03_Factor_SubScores'!M10:P10)*0.7+'02_Market_Inputs'!U10*0.3) | S10: =MIN(100,MAX(0,AVERAGE('03_Factor_SubScores'!Q10:R10)+MIN(10,'06_MLR_Regression'!G10)+MIN(15,'07_VAR_Granger'!I10*3))) | T10: =MIN(100,MAX(0,'03_Factor_SubScores'!S10*0.3+'03_Factor_SubScores'!T10*0.7)) | U10: =MIN(100,MAX(0,AVERAGE('03_Factor_SubScores'!U10:W10)))
A11: ='03_Factor_SubScores'!A11 | B11: ='03_Factor_SubScores'!B11 | C11: =ROUND(P11,2) | D11: =ROUND(Q11,2) | E11: =ROUND(R11,2) | F11: =ROUND(S11,2) | G11: =ROUND(T11,2) | H11: =ROUND(U11,2) | I11: =ROUND(P11*'01_Model_Config'!$C$6,2) | J11: =ROUND(Q11*'01_Model_Config'!$C$7,2) | K11: =ROUND(R11*'01_Model_Config'!$C$8,2) | L11: =ROUND(S11*'01_Model_Config'!$C$9,2) | M11: =ROUND(T11*'01_Model_Config'!$C$10,2) | N11: =ROUND(U11*'01_Model_Config'!$C$11,2) | O11: =SUM(I11:N11) | P11: =AVERAGE('03_Factor_SubScores'!C11:G11) | Q11: =IF('02_Market_Inputs'!O11<-2,MIN(20,IF('02_Market_Inputs'!P11>0,AVERAGE('03_Factor_SubScores'!H11:L11),AVERAGE('03_Factor_SubScores'!H11:K11))),IF('02_Market_Inputs'!P11>0,AVERAGE('03_Factor_SubScores'!H11:L11),AVERAGE('03_Factor_SubScores'!H11:K11))) | R11: =IF(ISBLANK('02_Market_Inputs'!U11),AVERAGE('03_Factor_SubScores'!M11:P11),AVERAGE('03_Factor_SubScores'!M11:P11)*0.7+'02_Market_Inputs'!U11*0.3) | S11: =MIN(100,MAX(0,AVERAGE('03_Factor_SubScores'!Q11:R11)+MIN(10,'06_MLR_Regression'!G11)+MIN(15,'07_VAR_Granger'!I11*3))) | T11: =MIN(100,MAX(0,'03_Factor_SubScores'!S11*0.3+'03_Factor_SubScores'!T11*0.7)) | U11: =MIN(100,MAX(0,AVERAGE('03_Factor_SubScores'!U11:W11)))
A12: ='03_Factor_SubScores'!A12 | B12: ='03_Factor_SubScores'!B12 | C12: =ROUND(P12,2) | D12: =ROUND(Q12,2) | E12: =ROUND(R12,2) | F12: =ROUND(S12,2) | G12: =ROUND(T12,2) | H12: =ROUND(U12,2) | I12: =ROUND(P12*'01_Model_Config'!$C$6,2) | J12: =ROUND(Q12*'01_Model_Config'!$C$7,2) | K12: =ROUND(R12*'01_Model_Config'!$C$8,2) | L12: =ROUND(S12*'01_Model_Config'!$C$9,2) | M12: =ROUND(T12*'01_Model_Config'!$C$10,2) | N12: =ROUND(U12*'01_Model_Config'!$C$11,2) | O12: =SUM(I12:N12) | P12: =AVERAGE('03_Factor_SubScores'!C12:G12) | Q12: =IF('02_Market_Inputs'!O12<-2,MIN(20,IF('02_Market_Inputs'!P12>0,AVERAGE('03_Factor_SubScores'!H12:L12),AVERAGE('03_Factor_SubScores'!H12:K12))),IF('02_Market_Inputs'!P12>0,AVERAGE('03_Factor_SubScores'!H12:L12),AVERAGE('03_Factor_SubScores'!H12:K12))) | R12: =IF(ISBLANK('02_Market_Inputs'!U12),AVERAGE('03_Factor_SubScores'!M12:P12),AVERAGE('03_Factor_SubScores'!M12:P12)*0.7+'02_Market_Inputs'!U12*0.3) | S12: =MIN(100,MAX(0,AVERAGE('03_Factor_SubScores'!Q12:R12)+MIN(10,'06_MLR_Regression'!G12)+MIN(15,'07_VAR_Granger'!I12*3))) | T12: =MIN(100,MAX(0,'03_Factor_SubScores'!S12*0.3+'03_Factor_SubScores'!T12*0.7)) | U12: =MIN(100,MAX(0,AVERAGE('03_Factor_SubScores'!U12:W12)))
A13: ='03_Factor_SubScores'!A13 | B13: ='03_Factor_SubScores'!B13 | C13: =ROUND(P13,2) | D13: =ROUND(Q13,2) | E13: =ROUND(R13,2) | F13: =ROUND(S13,2) | G13: =ROUND(T13,2) | H13: =ROUND(U13,2) | I13: =ROUND(P13*'01_Model_Config'!$C$6,2) | J13: =ROUND(Q13*'01_Model_Config'!$C$7,2) | K13: =ROUND(R13*'01_Model_Config'!$C$8,2) | L13: =ROUND(S13*'01_Model_Config'!$C$9,2) | M13: =ROUND(T13*'01_Model_Config'!$C$10,2) | N13: =ROUND(U13*'01_Model_Config'!$C$11,2) | O13: =SUM(I13:N13) | P13: =AVERAGE('03_Factor_SubScores'!C13:G13) | Q13: =IF('02_Market_Inputs'!O13<-2,MIN(20,IF('02_Market_Inputs'!P13>0,AVERAGE('03_Factor_SubScores'!H13:L13),AVERAGE('03_Factor_SubScores'!H13:K13))),IF('02_Market_Inputs'!P13>0,AVERAGE('03_Factor_SubScores'!H13:L13),AVERAGE('03_Factor_SubScores'!H13:K13))) | R13: =IF(ISBLANK('02_Market_Inputs'!U13),AVERAGE('03_Factor_SubScores'!M13:P13),AVERAGE('03_Factor_SubScores'!M13:P13)*0.7+'02_Market_Inputs'!U13*0.3) | S13: =MIN(100,MAX(0,AVERAGE('03_Factor_SubScores'!Q13:R13)+MIN(10,'06_MLR_Regression'!G13)+MIN(15,'07_VAR_Granger'!I13*3))) | T13: =MIN(100,MAX(0,'03_Factor_SubScores'!S13*0.3+'03_Factor_SubScores'!T13*0.7)) | U13: =MIN(100,MAX(0,AVERAGE('03_Factor_SubScores'!U13:W13)))
A14: ='03_Factor_SubScores'!A14 | B14: ='03_Factor_SubScores'!B14 | C14: =ROUND(P14,2) | D14: =ROUND(Q14,2) | E14: =ROUND(R14,2) | F14: =ROUND(S14,2) | G14: =ROUND(T14,2) | H14: =ROUND(U14,2) | I14: =ROUND(P14*'01_Model_Config'!$C$6,2) | J14: =ROUND(Q14*'01_Model_Config'!$C$7,2) | K14: =ROUND(R14*'01_Model_Config'!$C$8,2) | L14: =ROUND(S14*'01_Model_Config'!$C$9,2) | M14: =ROUND(T14*'01_Model_Config'!$C$10,2) | N14: =ROUND(U14*'01_Model_Config'!$C$11,2) | O14: =SUM(I14:N14) | P14: =AVERAGE('03_Factor_SubScores'!C14:G14) | Q14: =IF('02_Market_Inputs'!O14<-2,MIN(20,IF('02_Market_Inputs'!P14>0,AVERAGE('03_Factor_SubScores'!H14:L14),AVERAGE('03_Factor_SubScores'!H14:K14))),IF('02_Market_Inputs'!P14>0,AVERAGE('03_Factor_SubScores'!H14:L14),AVERAGE('03_Factor_SubScores'!H14:K14))) | R14: =IF(ISBLANK('02_Market_Inputs'!U14),AVERAGE('03_Factor_SubScores'!M14:P14),AVERAGE('03_Factor_SubScores'!M14:P14)*0.7+'02_Market_Inputs'!U14*0.3) | S14: =MIN(100,MAX(0,AVERAGE('03_Factor_SubScores'!Q14:R14)+MIN(10,'06_MLR_Regression'!G14)+MIN(15,'07_VAR_Granger'!I14*3))) | T14: =MIN(100,MAX(0,'03_Factor_SubScores'!S14*0.3+'03_Factor_SubScores'!T14*0.7)) | U14: =MIN(100,MAX(0,AVERAGE('03_Factor_SubScores'!U14:W14)))
A15: ='03_Factor_SubScores'!A15 | B15: ='03_Factor_SubScores'!B15 | C15: =ROUND(P15,2) | D15: =ROUND(Q15,2) | E15: =ROUND(R15,2) | F15: =ROUND(S15,2) | G15: =ROUND(T15,2) | H15: =ROUND(U15,2) | I15: =ROUND(P15*'01_Model_Config'!$C$6,2) | J15: =ROUND(Q15*'01_Model_Config'!$C$7,2) | K15: =ROUND(R15*'01_Model_Config'!$C$8,2) | L15: =ROUND(S15*'01_Model_Config'!$C$9,2) | M15: =ROUND(T15*'01_Model_Config'!$C$10,2) | N15: =ROUND(U15*'01_Model_Config'!$C$11,2) | O15: =SUM(I15:N15) | P15: =AVERAGE('03_Factor_SubScores'!C15:G15) | Q15: =IF('02_Market_Inputs'!O15<-2,MIN(20,IF('02_Market_Inputs'!P15>0,AVERAGE('03_Factor_SubScores'!H15:L15),AVERAGE('03_Factor_SubScores'!H15:K15))),IF('02_Market_Inputs'!P15>0,AVERAGE('03_Factor_SubScores'!H15:L15),AVERAGE('03_Factor_SubScores'!H15:K15))) | R15: =IF(ISBLANK('02_Market_Inputs'!U15),AVERAGE('03_Factor_SubScores'!M15:P15),AVERAGE('03_Factor_SubScores'!M15:P15)*0.7+'02_Market_Inputs'!U15*0.3) | S15: =MIN(100,MAX(0,AVERAGE('03_Factor_SubScores'!Q15:R15)+MIN(10,'06_MLR_Regression'!G15)+MIN(15,'07_VAR_Granger'!I15*3))) | T15: =MIN(100,MAX(0,'03_Factor_SubScores'!S15*0.3+'03_Factor_SubScores'!T15*0.7)) | U15: =MIN(100,MAX(0,AVERAGE('03_Factor_SubScores'!U15:W15)))
A16: ='03_Factor_SubScores'!A16 | B16: ='03_Factor_SubScores'!B16 | C16: =ROUND(P16,2) | D16: =ROUND(Q16,2) | E16: =ROUND(R16,2) | F16: =ROUND(S16,2) | G16: =ROUND(T16,2) | H16: =ROUND(U16,2) | I16: =ROUND(P16*'01_Model_Config'!$C$6,2) | J16: =ROUND(Q16*'01_Model_Config'!$C$7,2) | K16: =ROUND(R16*'01_Model_Config'!$C$8,2) | L16: =ROUND(S16*'01_Model_Config'!$C$9,2) | M16: =ROUND(T16*'01_Model_Config'!$C$10,2) | N16: =ROUND(U16*'01_Model_Config'!$C$11,2) | O16: =SUM(I16:N16) | P16: =AVERAGE('03_Factor_SubScores'!C16:G16) | Q16: =IF('02_Market_Inputs'!O16<-2,MIN(20,IF('02_Market_Inputs'!P16>0,AVERAGE('03_Factor_SubScores'!H16:L16),AVERAGE('03_Factor_SubScores'!H16:K16))),IF('02_Market_Inputs'!P16>0,AVERAGE('03_Factor_SubScores'!H16:L16),AVERAGE('03_Factor_SubScores'!H16:K16))) | R16: =IF(ISBLANK('02_Market_Inputs'!U16),AVERAGE('03_Factor_SubScores'!M16:P16),AVERAGE('03_Factor_SubScores'!M16:P16)*0.7+'02_Market_Inputs'!U16*0.3) | S16: =MIN(100,MAX(0,AVERAGE('03_Factor_SubScores'!Q16:R16)+MIN(10,'06_MLR_Regression'!G16)+MIN(15,'07_VAR_Granger'!I16*3))) | T16: =MIN(100,MAX(0,'03_Factor_SubScores'!S16*0.3+'03_Factor_SubScores'!T16*0.7)) | U16: =MIN(100,MAX(0,AVERAGE('03_Factor_SubScores'!U16:W16)))
... A28: ='03_Factor_SubScores'!A28 | B28: ='03_Factor_SubScores'!B28 | C28: =ROUND(P28,2) | D28: =ROUND(Q28,2) | E28: =ROUND(R28,2) | F28: =ROUND(S28,2) | G28: =ROUND(T28,2) | H28: =ROUND(U28,2) | I28: =ROUND(P28*'01_Model_Config'!$C$6,2) | J28: =ROUND(Q28*'01_Model_Config'!$C$7,2) | K28: =ROUND(R28*'01_Model_Config'!$C$8,2) | L28: =ROUND(S28*'01_Model_Config'!$C$9,2) | M28: =ROUND(T28*'01_Model_Config'!$C$10,2) | N28: =ROUND(U28*'01_Model_Config'!$C$11,2) | O28: =SUM(I28:N28) | P28: =AVERAGE('03_Factor_SubScores'!C28:G28) | Q28: =IF('02_Market_Inputs'!O28<-2,MIN(20,IF('02_Market_Inputs'!P28>0,AVERAGE('03_Factor_SubScores'!H28:L28),AVERAGE('03_Factor_SubScores'!H28:K28))),IF('02_Market_Inputs'!P28>0,AVERAGE('03_Factor_SubScores'!H28:L28),AVERAGE('03_Factor_SubScores'!H28:K28))) | R28: =IF(ISBLANK('02_Market_Inputs'!U28),AVERAGE('03_Factor_SubScores'!M28:P28),AVERAGE('03_Factor_SubScores'!M28:P28)*0.7+'02_Market_Inputs'!U28*0.3) | S28: =MIN(100,MAX(0,AVERAGE('03_Factor_SubScores'!Q28:R28)+MIN(10,'06_MLR_Regression'!G28)+MIN(15,'07_VAR_Granger'!I28*3))) | T28: =MIN(100,MAX(0,'03_Factor_SubScores'!S28*0.3+'03_Factor_SubScores'!T28*0.7)) | U28: =MIN(100,MAX(0,AVERAGE('03_Factor_SubScores'!U28:W28)))

Sheet 05_Composite_Calibration
A1: TWO-TIER COMPOSITE & EXPANDING CALIBRATION (v2)
A2: N<4: calibrated = raw | N≥4: σeff=MAX(σprior, min_std)·z capped ±z_cap·cal = clip(50+15×z_eff, Raw∓max_dist, 0..100); prior quarters only
A4: Quarter | B4: As-of Date | C4: As-of Close | D4: Raw Score | E4: Raw Label | F4: Prior N | G4: Prior Mean | H4: Prior Std | I4: Z-Score | J4: Calibrated Score | K4: Calibrated Label | L4: Suggested Allocation | M4: Pillar Std | N4: Pillar Range | O4: Dispersion | P4: Percentile Label | Q4: P15 Prior | R4: P85 Prior | S4: Rounded Raw Rank Key
A5: ='04_Pillar_Calculation'!A5 | B5: ='04_Pillar_Calculation'!B5 | C5: ='02_Market_Inputs'!C5 | D5: ='04_Pillar_Calculation'!O5 | E5: =IF(D5>='01_Model_Config'!$A$16,'01_Model_Config'!$C$16,IF(D5>='01_Model_Config'!$A$17,'01_Model_Config'!$C$17,IF(D5>='01_Model_Config'!$A$18,'01_Model_Config'!$C$18,IF(D5>='01_Model_Config'!$A$19,'01_Model_Config'!$C$19,'01_Model_Config'!$C$20)))) | F5: =ROWS($D$5:D5)-1 | G5: =IF(F5<'01_Model_Config'!$B$26,"","") | H5: =IF(F5<'01_Model_Config'!$B$26,"","") | I5: =IF(F5<'01_Model_Config'!$B$26,"",MIN('01_Model_Config'!$B$41,MAX(-'01_Model_Config'!$B$41,(D5-G5)/MAX(H5,'01_Model_Config'!$B$40)))) | J5: =ROUND(IF(F5<'01_Model_Config'!$B$26,D5,MIN('01_Model_Config'!$B$28,MAX('01_Model_Config'!$B$27,MIN(D5+'01_Model_Config'!$B$42,MAX(D5-'01_Model_Config'!$B$42,'01_Model_Config'!$B$24+'01_Model_Config'!$B$25*I5))))),2) | K5: =IF(J5>='01_Model_Config'!$A$16,'01_Model_Config'!$C$16,IF(J5>='01_Model_Config'!$A$17,'01_Model_Config'!$C$17,IF(J5>='01_Model_Config'!$A$18,'01_Model_Config'!$C$18,IF(J5>='01_Model_Config'!$A$19,'01_Model_Config'!$C$19,'01_Model_Config'!$C$20)))) | L5: =IF(J5>='01_Model_Config'!$A$16,'01_Model_Config'!$E$16,IF(J5>='01_Model_Config'!$A$17,'01_Model_Config'!$E$17,IF(J5>='01_Model_Config'!$A$18,'01_Model_Config'!$E$18,IF(J5>='01_Model_Config'!$A$19,'01_Model_Config'!$E$19,'01_Model_Config'!$E$20)))) | M5: =ROUND(STDEV.S('04_Pillar_Calculation'!C5:H5),2) | N5: =ROUND(MAX('04_Pillar_Calculation'!C5:H5)-MIN('04_Pillar_Calculation'!C5:H5),2) | O5: ="MEDIUM" | P5: ="HOLD" | Q5: =IF(F5<'01_Model_Config'!$B$26,"","") | R5: =IF(F5<'01_Model_Config'!$B$26,"","") | S5: =ROUND(D5,2)
A6: ='04_Pillar_Calculation'!A6 | B6: ='04_Pillar_Calculation'!B6 | C6: ='02_Market_Inputs'!C6 | D6: ='04_Pillar_Calculation'!O6 | E6: =IF(D6>='01_Model_Config'!$A$16,'01_Model_Config'!$C$16,IF(D6>='01_Model_Config'!$A$17,'01_Model_Config'!$C$17,IF(D6>='01_Model_Config'!$A$18,'01_Model_Config'!$C$18,IF(D6>='01_Model_Config'!$A$19,'01_Model_Config'!$C$19,'01_Model_Config'!$C$20)))) | F6: =ROWS($D$5:D6)-1 | G6: =IF(F6<'01_Model_Config'!$B$26,"",AVERAGE($D$5:D5)) | H6: =IF(F6<'01_Model_Config'!$B$26,"",STDEV.S($D$5:D5)) | I6: =IF(F6<'01_Model_Config'!$B$26,"",MIN('01_Model_Config'!$B$41,MAX(-'01_Model_Config'!$B$41,(D6-G6)/MAX(H6,'01_Model_Config'!$B$40)))) | J6: =ROUND(IF(F6<'01_Model_Config'!$B$26,D6,MIN('01_Model_Config'!$B$28,MAX('01_Model_Config'!$B$27,MIN(D6+'01_Model_Config'!$B$42,MAX(D6-'01_Model_Config'!$B$42,'01_Model_Config'!$B$24+'01_Model_Config'!$B$25*I6))))),2) | K6: =IF(J6>='01_Model_Config'!$A$16,'01_Model_Config'!$C$16,IF(J6>='01_Model_Config'!$A$17,'01_Model_Config'!$C$17,IF(J6>='01_Model_Config'!$A$18,'01_Model_Config'!$C$18,IF(J6>='01_Model_Config'!$A$19,'01_Model_Config'!$C$19,'01_Model_Config'!$C$20)))) | L6: =IF(J6>='01_Model_Config'!$A$16,'01_Model_Config'!$E$16,IF(J6>='01_Model_Config'!$A$17,'01_Model_Config'!$E$17,IF(J6>='01_Model_Config'!$A$18,'01_Model_Config'!$E$18,IF(J6>='01_Model_Config'!$A$19,'01_Model_Config'!$E$19,'01_Model_Config'!$E$20)))) | M6: =ROUND(STDEV.S('04_Pillar_Calculation'!C6:H6),2) | N6: =ROUND(MAX('04_Pillar_Calculation'!C6:H6)-MIN('04_Pillar_Calculation'!C6:H6),2) | O6: =IF(F6<'01_Model_Config'!$B$26,"MEDIUM",IF(M6>=PERCENTILE.INC($M$5:M5,0.67),"HIGH",IF(M6<=PERCENTILE.INC($M$5:M5,0.33),"LOW","MEDIUM"))) | P6: =IF(F6<'01_Model_Config'!$B$26,"HOLD",IF(D6>=R6,"BUY/ACCUMULATE",IF(D6<=Q6,"REDUCE/SELL","HOLD"))) | Q6: =IF(F6<'01_Model_Config'!$B$26,"",PERCENTILE.INC($D$5:D5,0.15)) | R6: =IF(F6<'01_Model_Config'!$B$26,"",PERCENTILE.INC($D$5:D5,0.85)) | S6: =ROUND(D6,2)
